Workbook
Name NativeTimeline_DATE: #N/A

Sheet Catalogue
A1: PRODUCT ID | B1: PRODUCT | C1: CATEGORY | D1: UOM | E1: BUYING PRICE | F1: SELLING PRICE
A2: P1001 | B2: Dove Soap | C2: Personal Care | D2: 100g bar | E2: 98 | F2: 129.36
A3: P1002 | B3: Colgate Toothpaste | C3: Personal Care | D3: 150g tube | E3: 105 | F3: 117.6
A4: P1003 | B4: Lifebuoy Handwash | C4: Personal Care | D4: 200ml bottle | E4: 44 | F4: 50.16
A5: P1004 | B5: Nivea Body Lotion | C5: Personal Care | D5: 400ml bottle | E5: 71 | F5: 80.23
A6: P1005 | B6: Gillette Shaving Foam | C6: Personal Care | D6: 200g can | E6: 133 | F6: 187.53
A7: P1006 | B7: Pantene Shampoo | C7: Personal Care | D7: 340ml bottle | E7: 124 | F7: 204.6
A8: P1007 | B8: Dettol Antiseptic Liquid | C8: Personal Care | D8: 250ml bottle | E8: 10 | F8: 11.2
A9: P1008 | B9: Himalaya Face Wash | C9: Personal Care | D9: 150ml tube | E9: 16 | F9: 17.6
A10: P1009 | B10: Vaseline Lip Care | C10: Personal Care | D10: 10g stick | E10: 10 | F10: 13.5
A11: P1010 | B11: Johnson’s Baby Powder | C11: Personal Care | D11: 500g bottle | E11: 123 | F11: 179.58
A12: P2001 | B12: Coca-Cola Can | C12: Beverages | D12: 330ml can | E12: 136 | F12: 179.52
A13: P2002 | B13: Pepsi Bottle | C13: Beverages | D13: 500ml bottle | E13: 12 | F13: 13.44
... A51: P5010 | B51: Wet Wipes - Himalaya | C51: Paper & Essentials | D51: 20 wipes | E51: 12 | F51: 17.52

Sheet Sheet7
A3: Row Labels | B3: Sum of SELLING VALUE | D3: Row Labels | E3: Sum of SELLING VALUE | G3: Row Labels | H3: Sum of SELLING VALUE | K3: Row Labels | L3: Sum of SELLING VALUE | M3: Sum of PROFIT | R3: Row Labels | S3: Sum of SELLING VALUE | W3: Row Labels | X3: Sum of SELLING VALUE | AA3: Row Labels | AB3: Sum of QTY
A4: Coca-Cola Can | B4: 12256.44 | D4: Beverages | E4: 100233.95 | G4: Jan | H4: 55973.89 | K4: Jan | L4: 29870.46 | M4: 6218.46 | R4: Cash | S4: 252031.48 | W4: Online | X4: 154019.16 | AA4: Online | AB4: 1576
A5: Dove Soap | B5: 11749.5 | D5: Household Cleaning | E5: 80011.81 | G5: Feb | H5: 49485.85 | K5: Feb | L5: 20204.85 | M5: 4160.85 | R5: Online | S5: 183788.96 | W5: Retail Sales | X5: 95499.7 | AA5: Retail Sales | AB5: 1012
A6: Minute Maid Pulpy | B6: 12760.37 | D6: Packaged Foods | E6: 86925.65 | G6: Mar | H6: 37519.15 | K6: Mar | L6: 35360.17 | M6: 8818.17 | R6: Grand Total | S6: 435820.44 | W6: Wholesaler | X6: 186301.58 | AA6: Wholesaler | AB6: 1982
A7: MTR Ready Curry | B7: 12392.23 | D7: Paper & Essentials | E7: 78653.68 | G7: Apr | H7: 21968.94 | K7: Apr | L7: 21968.94 | M7: 5192.94 | W7: Grand Total | X7: 435820.44 | AA7: Grand Total | AB7: 4570
A8: Nivea Body Lotion | B8: 12863.12 | D8: Personal Care | E8: 89995.35 | G8: May | H8: 31424.58 | K8: May | L8: 31424.58 | M8: 4949.58
A9: Real Mixed Fruit Juice | B9: 12812.35 | D9: Grand Total | E9: 435820.44 | G9: Jun | H9: 33370.03 | K9: Jun | L9: 33370.03 | M9: 9492.03
A10: Surf Excel Detergent | B10: 12052.58 | G10: Jul | H10: 32734.8 | K10: Jul | L10: 32734.8 | M10: 7602.8
A11: Top Ramen | B11: 11530.43 | G11: Aug | H11: 33709.95 | K11: Aug | L11: 33709.95 | M11: 7122.95
A12: Tropicana Orange Juice | B12: 12233.76 | G12: Sep | H12: 38926.74 | K12: Sep | L12: 38926.74 | M12: 10702.74
A13: Yippee Noodles | B13: 11598.76 | G13: Oct | H13: 34754.9 | K13: Oct | L13: 34754.9 | M13: 7623.9
A14: Grand Total | B14: 122249.54 | G14: Nov | H14: 31789.88 | K14: Nov | L14: 31789.88 | M14: 6000.88
G15: Dec | H15: 34161.73 | K15: Dec | L15: 34161.73 | M15: 8472.73
G16: Grand Total | H16: 435820.44 | K16: Grand Total | L16: 378277.03 | M16: 86358.03

Sheet Sales Report
A1: DATE | B1: PRODUCT ID | C1: QTY | D1: SALES TYPE | E1: PAYMENT MODE | F1: BUYING PRICE | G1: SELLING PRICE | H1: COST VALUE | I1: SELLING VALUE | J1: PROFIT | K1: PRODUCT | L1: MONTH | M1: CATEGORY
A2: 45292 | B2: P3004 | C2: 10 | D2: Wholesaler | E2: Online | F2: =VLOOKUP(B2,Catalogue!$A$1:$F$51,5,FALSE) -> 136 | G2: =VLOOKUP(B2,Catalogue!$A$1:$F$51,6,FALSE) -> 153.68 | H2: =C2*F2 -> 1360 | I2: =C2*G2 -> 1536.8 | J2: =I2-H2 -> 176.8 | K2: {=Catalogue!B2:B51} -> Dove Soap | L2: =TEXT(A2,"mmm") -> Jan | M2: {=Catalogue!C2:C51} -> Personal Care
A3: 45293 | B3: P5001 | C3: 2 | D3: Online | E3: Cash | F3: =VLOOKUP(B3,Catalogue!$A$1:$F$51,5,FALSE) -> 44 | G3: =VLOOKUP(B3,Catalogue!$A$1:$F$51,6,FALSE) -> 58.08 | H3: =C3*F3 -> 88 | I3: =C3*G3 -> 116.16 | J3: =I3-H3 -> 28.16 | K3: Colgate Toothpaste | L3: =TEXT(A3,"mmm") -> Jan | M3: Personal Care
A4: 45294 | B4: P3003 | C4: 2 | D4: Retail Sales | E4: Cash | F4: =VLOOKUP(B4,Catalogue!$A$1:$F$51,5,FALSE) -> 123 | G4: =VLOOKUP(B4,Catalogue!$A$1:$F$51,6,FALSE) -> 140.22 | H4: =C4*F4 -> 246 | I4: =C4*G4 -> 280.44 | J4: =I4-H4 -> 34.44 | K4: Lifebuoy Handwash | L4: =TEXT(A4,"mmm") -> Jan | M4: Personal Care
A5: 45295 | B5: P5010 | C5: 11 | D5: Retail Sales | E5: Online | F5: =VLOOKUP(B5,Catalogue!$A$1:$F$51,5,FALSE) -> 12 | G5: =VLOOKUP(B5,Catalogue!$A$1:$F$51,6,FALSE) -> 17.52 | H5: =C5*F5 -> 132 | I5: =C5*G5 -> 192.72 | J5: =I5-H5 -> 60.72 | K5: Nivea Body Lotion | L5: =TEXT(A5,"mmm") -> Jan | M5: Personal Care
A6: 45296 | B6: P5001 | C6: 18 | D6: Online | E6: Cash | F6: =VLOOKUP(B6,Catalogue!$A$1:$F$51,5,FALSE) -> 44 | G6: =VLOOKUP(B6,Catalogue!$A$1:$F$51,6,FALSE) -> 58.08 | H6: =C6*F6 -> 792 | I6: =C6*G6 -> 1045.44 | J6: =I6-H6 -> 253.44 | K6: Gillette Shaving Foam | L6: =TEXT(A6,"mmm") -> Jan | M6: Personal Care
A7: 45297 | B7: P1007 | C7: 10 | D7: Wholesaler | E7: Online | F7: =VLOOKUP(B7,Catalogue!$A$1:$F$51,5,FALSE) -> 10 | G7: =VLOOKUP(B7,Catalogue!$A$1:$F$51,6,FALSE) -> 11.2 | H7: =C7*F7 -> 100 | I7: =C7*G7 -> 112 | J7: =I7-H7 -> 12 | K7: Pantene Shampoo | L7: =TEXT(A7,"mmm") -> Jan | M7: Personal Care
A8: 45298 | B8: P5006 | C8: 14 | D8: Wholesaler | E8: Cash | F8: =VLOOKUP(B8,Catalogue!$A$1:$F$51,5,FALSE) -> 16 | G8: =VLOOKUP(B8,Catalogue!$A$1:$F$51,6,FALSE) -> 26.4 | H8: =C8*F8 -> 224 | I8: =C8*G8 -> 369.6 | J8: =I8-H8 -> 145.6 | K8: Dettol Antiseptic Liquid | L8: =TEXT(A8,"mmm") -> Jan | M8: Personal Care
A9: 45299 | B9: P3008 | C9: 10 | D9: Online | E9: Online | F9: =VLOOKUP(B9,Catalogue!$A$1:$F$51,5,FALSE) -> 44 | G9: =VLOOKUP(B9,Catalogue!$A$1:$F$51,6,FALSE) -> 48.4 | H9: =C9*F9 -> 440 | I9: =C9*G9 -> 484 | J9: =I9-H9 -> 44 | K9: Himalaya Face Wash | L9: =TEXT(A9,"mmm") -> Jan | M9: Personal Care
A10: 45300 | B10: P4001 | C10: 16 | D10: Wholesaler | E10: Cash | F10: =VLOOKUP(B10,Catalogue!$A$1:$F$51,5,FALSE) -> 124 | G10: =VLOOKUP(B10,Catalogue!$A$1:$F$51,6,FALSE) -> 163.68 | H10: =C10*F10 -> 1984 | I10: =C10*G10 -> 2618.88 | J10: =I10-H10 -> 634.88 | K10: Vaseline Lip Care | L10: =TEXT(A10,"mmm") -> Jan | M10: Personal Care
A11: 45301 | B11: P4004 | C11: 14 | D11: Wholesaler | E11: Cash | F11: =VLOOKUP(B11,Catalogue!$A$1:$F$51,5,FALSE) -> 10 | G11: =VLOOKUP(B11,Catalogue!$A$1:$F$51,6,FALSE) -> 11.3 | H11: =C11*F11 -> 140 | I11: =C11*G11 -> 158.2 | J11: =I11-H11 -> 18.2 | K11: Johnson’s Baby Powder | L11: =TEXT(A11,"mmm") -> Jan | M11: Personal Care
A12: 45302 | B12: P3003 | C12: 17 | D12: Online | E12: Online | F12: =VLOOKUP(B12,Catalogue!$A$1:$F$51,5,FALSE) -> 123 | G12: =VLOOKUP(B12,Catalogue!$A$1:$F$51,6,FALSE) -> 140.22 | H12: =C12*F12 -> 2091 | I12: =C12*G12 -> 2383.74 | J12: =I12-H12 -> 292.74 | K12: Coca-Cola Can | L12: =TEXT(A12,"mmm") -> Jan | M12: Beverages
A13: 45303 | B13: P2002 | C13: 10 | D13: Retail Sales | E13: Cash | F13: =VLOOKUP(B13,Catalogue!$A$1:$F$51,5,FALSE) -> 12 | G13: =VLOOKUP(B13,Catalogue!$A$1:$F$51,6,FALSE) -> 13.44 | H13: =C13*F13 -> 120 | I13: =C13*G13 -> 134.4 | J13: =I13-H13 -> 14.4 | K13: Pepsi Bottle | L13: =TEXT(A13,"mmm") -> Jan | M13: Beverages
A14: 45304 | B14: P5009 | C14: 8 | D14: Retail Sales | E14: Cash | F14: =VLOOKUP(B14,Catalogue!$A$1:$F$51,5,FALSE) -> 136 | G14: =VLOOKUP(B14,Catalogue!$A$1:$F$51,6,FALSE) -> 183.6 | H14: =C14*F14 -> 1088 | I14: =C14*G14 -> 1468.8 | J14: =I14-H14 -> 380.8 | K14: Red Bull | L14: =TEXT(A14,"mmm") -> Jan | M14: Beverages
... A51: 45341 | B51: P3002 | C51: 8 | D51: Online | E51: Cash | F51: =VLOOKUP(B51,Catalogue!$A$1:$F$51,5,FALSE) -> 10 | G51: =VLOOKUP(B51,Catalogue!$A$1:$F$51,6,FALSE) -> 11.2 | H51: =C51*F51 -> 80 | I51: =C51*G51 -> 89.6 | J51: =I51-H51 -> 9.6 | K51: Wet Wipes - Himalaya | L51: =TEXT(A51,"mmm") -> Feb | M51: Paper & Essentials
A52: 45342 | B52: P4005 | C52: 5 | D52: Wholesaler | E52: Online | F52: =VLOOKUP(B52,Catalogue!$A$1:$F$51,5,FALSE) -> 123 | G52: =VLOOKUP(B52,Catalogue!$A$1:$F$51,6,FALSE) -> 173.43 | H52: =C52*F52 -> 615 | I52: =C52*G52 -> 867.15 | J52: =I52-H52 -> 252.15 | K52: {=Catalogue!B2:B51} -> Dove Soap | L52: =TEXT(A52,"mmm") -> Feb | M52: {=Catalogue!C2:C51} -> Personal Care
A53: 45343 | B53: P1008 | C53: 20 | D53: Wholesaler | E53: Cash | F53: =VLOOKUP(B53,Catalogue!$A$1:$F$51,5,FALSE) -> 16 | G53: =VLOOKUP(B53,Catalogue!$A$1:$F$51,6,FALSE) -> 17.6 | H53: =C53*F53 -> 320 | I53: =C53*G53 -> 352 | J53: =I53-H53 -> 32 | K53: Colgate Toothpaste | L53: =TEXT(A53,"mmm") -> Feb | M53: Personal Care
A54: 45344 | B54: P3008 | C54: 10 | D54: Online | E54: Cash | F54: =VLOOKUP(B54,Catalogue!$A$1:$F$51,5,FALSE) -> 44 | G54: =VLOOKUP(B54,Catalogue!$A$1:$F$51,6,FALSE) -> 48.4 | H54: =C54*F54 -> 440 | I54: =C54*G54 -> 484 | J54: =I54-H54 -> 44 | K54: Lifebuoy Handwash | L54: =TEXT(A54,"mmm") -> Feb | M54: Personal Care
A55: 45345 | B55: P5006 | C55: 12 | D55: Wholesaler | E55: Online | F55: =VLOOKUP(B55,Catalogue!$A$1:$F$51,5,FALSE) -> 16 | G55: =VLOOKUP(B55,Catalogue!$A$1:$F$51,6,FALSE) -> 26.4 | H55: =C55*F55 -> 192 | I55: =C55*G55 -> 316.8 | J55: =I55-H55 -> 124.8 | K55: Nivea Body Lotion | L55: =TEXT(A55,"mmm") -> Feb | M55: Personal Care
A56: 45346 | B56: P5010 | C56: 5 | D56: Wholesaler | E56: Cash | F56: =VLOOKUP(B56,Catalogue!$A$1:$F$51,5,FALSE) -> 12 | G56: =VLOOKUP(B56,Catalogue!$A$1:$F$51,6,FALSE) -> 17.52 | H56: =C56*F56 -> 60 | I56: =C56*G56 -> 87.6 | J56: =I56-H56 -> 27.6 | K56: Gillette Shaving Foam | L56: =TEXT(A56,"mmm") -> Feb | M56: Personal Care
A57: 45347 | B57: P5006 | C57: 3 | D57: Online | E57: Online | F57: =VLOOKUP(B57,Catalogue!$A$1:$F$51,5,FALSE) -> 16 | G57: =VLOOKUP(B57,Catalogue!$A$1:$F$51,6,FALSE) -> 26.4 | H57: =C57*F57 -> 48 | I57: =C57*G57 -> 79.2 | J57: =I57-H57 -> 31.2 | K57: Pantene Shampoo | L57: =TEXT(A57,"mmm") -> Feb | M57: Personal Care
A58: 45348 | B58: P5005 | C58: 8 | D58: Retail Sales | E58: Cash | F58: =VLOOKUP(B58,Catalogue!$A$1:$F$51,5,FALSE) -> 10 | G58: =VLOOKUP(B58,Catalogue!$A$1:$F$51,6,FALSE) -> 14.1 | H58: =C58*F58 -> 80 | I58: =C58*G58 -> 112.8 | J58: =I58-H58 -> 32.8 | K58: Dettol Antiseptic Liquid | L58: =TEXT(A58,"mmm") -> Feb | M58: Personal Care
A59: 45349 | B59: P3004 | C59: 7 | D59: Retail Sales | E59: Online | F59: =VLOOKUP(B59,Catalogue!$A$1:$F$51,5,FALSE) -> 136 | G59: =VLOOKUP(B59,Catalogue!$A$1:$F$51,6,FALSE) -> 153.68 | H59: =C59*F59 -> 952 | I59: =C59*G59 -> 1075.76 | J59: =I59-H59 -> 123.76 | K59: Himalaya Face Wash | L59: =TEXT(A59,"mmm") -> Feb | M59: Personal Care
A60: 45350 | B60: P3001 | C60: 6 | D60: Online | E60: Cash | F60: =VLOOKUP(B60,Catalogue!$A$1:$F$51,5,FALSE) -> 16 | G60: =VLOOKUP(B60,Catalogue!$A$1:$F$51,6,FALSE) -> 21.12 | H60: =C60*F60 -> 96 | I60: =C60*G60 -> 126.72 | J60: =I60-H60 -> 30.72 | K60: Vaseline Lip Care | L60: =TEXT(A60,"mmm") -> Feb | M60: Personal Care
A61: 45351 | B61: P5008 | C61: 1 | D61: Wholesaler | E61: Cash | F61: =VLOOKUP(B61,Catalogue!$A$1:$F$51,5,FALSE) -> 123 | G61: =VLOOKUP(B61,Catalogue!$A$1:$F$51,6,FALSE) -> 135.3 | H61: =C61*F61 -> 123 | I61: =C61*G61 -> 135.3 | J61: =I61-H61 -> 12.3 | K61: Johnson’s Baby Powder | L61: =TEXT(A61,"mmm") -> Feb | M61: Personal Care
A62: 45352 | B62: P3009 | C62: 14 | D62: Wholesaler | E62: Online | F62: =VLOOKUP(B62,Catalogue!$A$1:$F$51,5,FALSE) -> 71 | G62: =VLOOKUP(B62,Catalogue!$A$1:$F$51,6,FALSE) -> 95.85 | H62: =C62*F62 -> 994 | I62: =C62*G62 -> 1341.9 | J62: =I62-H62 -> 347.9 | K62: Coca-Cola Can | L62: =TEXT(A62,"mmm") -> Mar | M62: Beverages
A63: 45353 | B63: P3009 | C63: 20 | D63: Online | E63: Cash | F63: =VLOOKUP(B63,Catalogue!$A$1:$F$51,5,FALSE) -> 71 | G63: =VLOOKUP(B63,Catalogue!$A$1:$F$51,6,FALSE) -> 95.85 | H63: =C63*F63 -> 1420 | I63: =C63*G63 -> 1917 | J63: =I63-H63 -> 497 | K63: Pepsi Bottle | L63: =TEXT(A63,"mmm") -> Mar | M63: Beverages
A64: 45354 | B64: P3007 | C64: 13 | D64: Wholesaler | E64: Cash | F64: =VLOOKUP(B64,Catalogue!$A$1:$F$51,5,FALSE) -> 105 | G64: =VLOOKUP(B64,Catalogue!$A$1:$F$51,6,FALSE) -> 117.6 | H64: =C64*F64 -> 1365 | I64: =C64*G64 -> 1528.8 | J64: =I64-H64 -> 163.8 | K64: Red Bull | L64: =TEXT(A64,"mmm") -> Mar | M64: Beverages
... A101: 45391 | B101: P1010 | C101: 6 | D101: Wholesaler | E101: Cash | F101: =VLOOKUP(B101,Catalogue!$A$1:$F$51,5,FALSE) -> 123 | G101: =VLOOKUP(B101,Catalogue!$A$1:$F$51,6,FALSE) -> 179.58 | H101: =C101*F101 -> 738 | I101: =C101*G101 -> 1077.48 | J101: =I101-H101 -> 339.48 | K101: Wet Wipes - Himalaya | L101: =TEXT(A101,"mmm") -> Apr | M101: Paper & Essentials
A102: 45392 | B102: P1001 | C102: 4 | D102: Online | E102: Online | F102: =VLOOKUP(B102,Catalogue!$A$1:$F$51,5,FALSE) -> 98 | G102: =VLOOKUP(B102,Catalogue!$A$1:$F$51,6,FALSE) -> 129.36 | H102: =C102*F102 -> 392 | I102: =C102*G102 -> 517.44 | J102: =I102-H102 -> 125.44 | K102: {=Catalogue!B2:B51} -> Dove Soap | L102: =TEXT(A102,"mmm") -> Apr | M102: {=Catalogue!C2:C51} -> Personal Care
A103: 45393 | B103: P5009 | C103: 9 | D103: Retail Sales | E103: Cash | F103: =VLOOKUP(B103,Catalogue!$A$1:$F$51,5,FALSE) -> 136 | G103: =VLOOKUP(B103,Catalogue!$A$1:$F$51,6,FALSE) -> 183.6 | H103: =C103*F103 -> 1224 | I103: =C103*G103 -> 1652.4 | J103: =I103-H103 -> 428.4 | K103: Colgate Toothpaste | L103: =TEXT(A103,"mmm") -> Apr | M103: Personal Care
A104: 45394 | B104: P1008 | C104: 9 | D104: Retail Sales | E104: Cash | F104: =VLOOKUP(B104,Catalogue!$A$1:$F$51,5,FALSE) -> 16 | G104: =VLOOKUP(B104,Catalogue!$A$1:$F$51,6,FALSE) -> 17.6 | H104: =C104*F104 -> 144 | I104: =C104*G104 -> 158.4 | J104: =I104-H104 -> 14.4 | K104: Lifebuoy Handwash | L104: =TEXT(A104,"mmm") -> Apr | M104: Personal Care
A105: 45395 | B105: P3005 | C105: 2 | D105: Online | E105: Online | F105: =VLOOKUP(B105,Catalogue!$A$1:$F$51,5,FALSE) -> 12 | G105: =VLOOKUP(B105,Catalogue!$A$1:$F$51,6,FALSE) -> 16.92 | H105: =C105*F105 -> 24 | I105: =C105*G105 -> 33.84 | J105: =I105-H105 -> 9.84 | K105: Nivea Body Lotion | L105: =TEXT(A105,"mmm") -> Apr | M105: Personal Care
A106: 45396 | B106: P3005 | C106: 15 | D106: Wholesaler | E106: Cash | F106: =VLOOKUP(B106,Catalogue!$A$1:$F$51,5,FALSE) -> 12 | G106: =VLOOKUP(B106,Catalogue!$A$1:$F$51,6,FALSE) -> 16.92 | H106: =C106*F106 -> 180 | I106: =C106*G106 -> 253.8 | J106: =I106-H106 -> 73.8 | K106: Gillette Shaving Foam | L106: =TEXT(A106,"mmm") -> Apr | M106: Personal Care
A107: 45397 | B107: P2006 | C107: 3 | D107: Wholesaler | E107: Online | F107: =VLOOKUP(B107,Catalogue!$A$1:$F$51,5,FALSE) -> 44 | G107: =VLOOKUP(B107,Catalogue!$A$1:$F$51,6,FALSE) -> 72.6 | H107: =C107*F107 -> 132 | I107: =C107*G107 -> 217.8 | J107: =I107-H107 -> 85.8 | K107: Pantene Shampoo | L107: =TEXT(A107,"mmm") -> Apr | M107: Personal Care
A108: 45398 | B108: P2006 | C108: 14 | D108: Online | E108: Cash | F108: =VLOOKUP(B108,Catalogue!$A$1:$F$51,5,FALSE) -> 44 | G108: =VLOOKUP(B108,Catalogue!$A$1:$F$51,6,FALSE) -> 72.6 | H108: =C108*F108 -> 616 | I108: =C108*G108 -> 1016.4 | J108: =I108-H108 -> 400.4 | K108: Dettol Antiseptic Liquid | L108: =TEXT(A108,"mmm") -> Apr | M108: Personal Care
A109: 45399 | B109: P5009 | C109: 3 | D109: Wholesaler | E109: Online | F109: =VLOOKUP(B109,Catalogue!$A$1:$F$51,5,FALSE) -> 136 | G109: =VLOOKUP(B109,Catalogue!$A$1:$F$51,6,FALSE) -> 183.6 | H109: =C109*F109 -> 408 | I109: =C109*G109 -> 550.8 | J109: =I109-H109 -> 142.8 | K109: Himalaya Face Wash | L109: =TEXT(A109,"mmm") -> Apr | M109: Personal Care
A110: 45400 | B110: P5010 | C110: 19 | D110: Wholesaler | E110: Cash | F110: =VLOOKUP(B110,Catalogue!$A$1:$F$51,5,FALSE) -> 12 | G110: =VLOOKUP(B110,Catalogue!$A$1:$F$51,6,FALSE) -> 17.52 | H110: =C110*F110 -> 228 | I110: =C110*G110 -> 332.88 | J110: =I110-H110 -> 104.88 | K110: Vaseline Lip Care | L110: =TEXT(A110,"mmm") -> Apr | M110: Personal Care
A111: 45401 | B111: P1005 | C111: 2 | D111: Online | E111: Cash | F111: =VLOOKUP(B111,Catalogue!$A$1:$F$51,5,FALSE) -> 133 | G111: =VLOOKUP(B111,Catalogue!$A$1:$F$51,6,FALSE) -> 187.53 | H111: =C111*F111 -> 266 | I111: =C111*G111 -> 375.06 | J111: =I111-H111 -> 109.06 | K111: Johnson’s Baby Powder | L111: =TEXT(A111,"mmm") -> Apr | M111: Personal Care
A112: 45402 | B112: P2001 | C112: 8 | D112: Retail Sales | E112: Online | F112: =VLOOKUP(B112,Catalogue!$A$1:$F$51,5,FALSE) -> 136 | G112: =VLOOKUP(B112,Catalogue!$A$1:$F$51,6,FALSE) -> 179.52 | H112: =C112*F112 -> 1088 | I112: =C112*G112 -> 1436.16 | J112: =I112-H112 -> 348.16 | K112: Coca-Cola Can | L112: =TEXT(A112,"mmm") -> Apr | M112: Beverages
...
